void main() {

	// CASE 1: When the exception to be thrown is known, we use ON Clause
	try {
		int result = 15 ~/ 0;
		print("The result is $result");
	} on IntegerDivisionByZeroException {
		print("Cannot divide by Zero");
	}
	
 	 // CASE 2: When the exception is unknown, we use CATCH Clause
	try {
		int result = 15 ~/ 0;
		print("The result is $result");
	} catch (e) {
		print("The exception thrown is $e");
	}
	
	// CASE 3: Using STACK TRACE to know the events occurred before Exception was thrown
	try {
		int result = 15 ~/ 0;
		print("The result is $result");
	} catch (e, s) {
		print("The exception thrown is $e");
		print("STACK TRACE \n $s");
	}
	
	// CASE 4: Whether there is an Exception or not, FINALLY Clause is always Executed
	try {
		int result = 15 ~/ 3;
		print("The result is $result");
	} catch (e) {
		print("The exception thrown is $e");
	} finally {
		print("This is FINALLY Clause and is always executed.");
	}
	
	// CASE 5: Custom Exception
	try {
		func(-20);
	} catch (e) {
		print(e.errorMessage());
	} finally {
		// Code
	}
	
}

class MyException implements Exception {
	String errorMessage() {
		return "You cannot enter number less than 0";
	}
}

void func(int num) {
	if (num < 0) {
		throw new MyException();
	}
}
  
